
Found 4 GPU devices, using 20 parallel workers for evaluating 160 total trajectories
Renderer is using size (200, 360)
---- Testing model test_any_task.TransformerNetwork ----
multiprocessing.pool.RemoteTraceback:
"""
Traceback (most recent call last):
  File "/raid/home/frosa_Loc/conda/envs/multi_task_lfd/lib/python3.9/multiprocessing/pool.py", line 125, in worker
    result = (True, func(*args, **kwds))
  File "/raid/home/frosa_Loc/conda/envs/multi_task_lfd/lib/python3.9/multiprocessing/pool.py", line 51, in starmapstar
    return list(itertools.starmap(args[0], args[1]))
  File "/raid/home/frosa_Loc/Language-Conditioned-Imitation-Learning/test/multi_task_test/test_any_task.py", line 265, in _proc
    return_rollout = rollout_imitation(model,
  File "/raid/home/frosa_Loc/Language-Conditioned-Imitation-Learning/test/multi_task_test/test_any_task.py", line 187, in rollout_imitation
    traj, info = eval_fn(model,
  File "/raid/home/frosa_Loc/Multi-Task-LFD-Framework/repo/Multi-Task-LFD-Training-Framework/test/multi_task_test/pick_place.py", line 707, in pick_place_eval
    return pick_place_eval_demo_cond(model=model,
  File "/raid/home/frosa_Loc/Multi-Task-LFD-Framework/repo/Multi-Task-LFD-Training-Framework/test/multi_task_test/pick_place.py", line 336, in pick_place_eval_demo_cond
    obs, reward, info, action, env_done, time_action = task_run_action(
  File "/raid/home/frosa_Loc/Multi-Task-LFD-Framework/repo/Multi-Task-LFD-Training-Framework/test/multi_task_test/utils.py", line 2096, in task_run_action
    action, target_pred, target_obj_emb, activation_map, prediction_internal_obj, predicted_bb = get_action(
TypeError: get_action() got an unexpected keyword argument 'controller'
"""
The above exception was the direct cause of the following exception:
Traceback (most recent call last):
  File "/raid/home/frosa_Loc/Language-Conditioned-Imitation-Learning/test/multi_task_test/test_any_task.py", line 627, in <module>
    task_success_flags = p.starmap(f, seeds)
  File "/raid/home/frosa_Loc/conda/envs/multi_task_lfd/lib/python3.9/multiprocessing/pool.py", line 372, in starmap
    return self._map_async(func, iterable, starmapstar, chunksize).get()
  File "/raid/home/frosa_Loc/conda/envs/multi_task_lfd/lib/python3.9/multiprocessing/pool.py", line 771, in get
    raise self._value
TypeError: get_action() got an unexpected keyword argument 'controller'
During handling of the above exception, another exception occurred:
Traceback (most recent call last):
  File "/raid/home/frosa_Loc/Language-Conditioned-Imitation-Learning/test/multi_task_test/test_any_task.py", line 627, in <module>
    task_success_flags = p.starmap(f, seeds)
  File "/raid/home/frosa_Loc/Language-Conditioned-Imitation-Learning/test/multi_task_test/test_any_task.py", line 627, in <module>
    task_success_flags = p.starmap(f, seeds)
  File "_pydevd_bundle/pydevd_cython.pyx", line 1457, in _pydevd_bundle.pydevd_cython.SafeCallWrapper.__call__
  File "_pydevd_bundle/pydevd_cython.pyx", line 1676, in _pydevd_bundle.pydevd_cython.TopLevelThreadTracerNoBackFrame.trace_dispatch_and_unhandled_exceptions
  File "_pydevd_bundle/pydevd_cython.pyx", line 701, in _pydevd_bundle.pydevd_cython.PyDBFrame.trace_dispatch
  File "_pydevd_bundle/pydevd_cython.pyx", line 1152, in _pydevd_bundle.pydevd_cython.PyDBFrame.trace_dispatch
  File "_pydevd_bundle/pydevd_cython.pyx", line 1135, in _pydevd_bundle.pydevd_cython.PyDBFrame.trace_dispatch
  File "_pydevd_bundle/pydevd_cython.pyx", line 312, in _pydevd_bundle.pydevd_cython.PyDBFrame.do_wait_suspend
  File "/raid/home/frosa_Loc/conda/envs/multi_task_lfd/lib/python3.9/site-packages/debugpy/_vendored/pydevd/pydevd.py", line 2070, in do_wait_suspend
    keep_suspended = self._do_wait_suspend(thread, frame, event, arg, suspend_type, from_this_thread, frames_tracker)
  File "/raid/home/frosa_Loc/conda/envs/multi_task_lfd/lib/python3.9/site-packages/debugpy/_vendored/pydevd/pydevd.py", line 2106, in _do_wait_suspend
    time.sleep(0.01)
KeyboardInterrupt